2024-04-09 13:26:56,253 - __main__ - DEBUG - Validating file: newTest.txt
2024-04-09 13:26:56,264 - __main__ - DEBUG - scan_result: {scan_result}
2024-04-09 13:39:18,332 - __main__ - DEBUG - Validating file: TESTINGDOC.txt
2024-04-09 13:39:18,344 - __main__ - DEBUG - scan_result: {scan_result}
2024-04-09 15:03:36,566 - __main__ - DEBUG - Validating file: ArchieGledhillCV.rtf
2024-04-09 15:03:36,575 - __main__ - DEBUG - scan_result: {scan_result}
2024-04-09 15:03:36,866 - __main__ - ERROR - Conversion failed: Traceback (most recent call last):
  File "/Users/ag/PycharmProjects/FileConversionServiceX/app.py", line 46, in convert_file
    converter.convert(output_stream)
  File "/Users/ag/PycharmProjects/FileConversionServiceX/converter_logic/rtf_to_txt_converter.py", line 27, in convert
    raise e
  File "/Users/ag/PycharmProjects/FileConversionServiceX/converter_logic/rtf_to_txt_converter.py", line 18, in convert
    subprocess.run(command, check=True, shell=True)
  File "/Library/Frameworks/Python.framework/Versions/3.12/lib/python3.12/subprocess.py", line 571, in run
    raise CalledProcessError(retcode, process.args,
subprocess.CalledProcessError: Command 'unrtf --text /var/folders/fh/ydk8l4t16ws2w9f2fctf7k_h0000gn/T/tmpemrof4ld.rtf > /var/folders/fh/ydk8l4t16ws2w9f2fctf7k_h0000gn/T/tmpemrof4ld.rtf.txt' returned non-zero exit status 1.

2024-04-09 15:05:31,898 - __main__ - DEBUG - Validating file: ArchieGledhillCV.rtf
2024-04-09 15:05:31,901 - __main__ - DEBUG - scan_result: {scan_result}
2024-04-09 15:05:32,156 - __main__ - ERROR - Conversion failed: Traceback (most recent call last):
  File "/Users/ag/PycharmProjects/FileConversionServiceX/app.py", line 46, in convert_file
    converter.convert(output_stream)
  File "/Users/ag/PycharmProjects/FileConversionServiceX/converter_logic/rtf_to_txt_converter.py", line 27, in convert
    raise e
  File "/Users/ag/PycharmProjects/FileConversionServiceX/converter_logic/rtf_to_txt_converter.py", line 18, in convert
    subprocess.run(command, check=True, shell=True)
  File "/Library/Frameworks/Python.framework/Versions/3.12/lib/python3.12/subprocess.py", line 571, in run
    raise CalledProcessError(retcode, process.args,
subprocess.CalledProcessError: Command 'unrtf --text /var/folders/fh/ydk8l4t16ws2w9f2fctf7k_h0000gn/T/tmpc6qcojv4.rtf > /var/folders/fh/ydk8l4t16ws2w9f2fctf7k_h0000gn/T/tmpc6qcojv4.rtf.txt' returned non-zero exit status 10.

2024-04-09 15:34:52,476 - __main__ - DEBUG - Validating file: ArchieGledhillCV_1.rtf
2024-04-09 15:34:52,484 - __main__ - DEBUG - scan_result: {scan_result}
2024-04-09 15:34:52,517 - __main__ - ERROR - Conversion failed: Traceback (most recent call last):
  File "/Users/ag/PycharmProjects/FileConversionServiceX/app.py", line 46, in convert_file
    converter.convert(output_stream)
  File "/Users/ag/PycharmProjects/FileConversionServiceX/converter_logic/rtf_to_txt_converter.py", line 27, in convert
    raise e
  File "/Users/ag/PycharmProjects/FileConversionServiceX/converter_logic/rtf_to_txt_converter.py", line 18, in convert
    subprocess.run(command, check=True, shell=True)
  File "/Library/Frameworks/Python.framework/Versions/3.12/lib/python3.12/subprocess.py", line 571, in run
    raise CalledProcessError(retcode, process.args,
subprocess.CalledProcessError: Command 'unrtf --text /var/folders/fh/ydk8l4t16ws2w9f2fctf7k_h0000gn/T/tmpkspgu_yg.rtf > /var/folders/fh/ydk8l4t16ws2w9f2fctf7k_h0000gn/T/tmpkspgu_yg.rtf.txt' returned non-zero exit status 10.

2024-04-09 16:38:44,896 - __main__ - DEBUG - Validating file: newTest.rtf
2024-04-09 16:38:44,902 - __main__ - DEBUG - scan_result: {scan_result}
2024-04-09 16:38:44,925 - converter_logic.rtf_to_txt_converter - ERROR - An error occurred during RTF to TXT conversion: Error (line 0): Cannot open input file

2024-04-09 16:38:44,929 - __main__ - ERROR - Conversion failed: Traceback (most recent call last):
  File "/Users/ag/PycharmProjects/FileConversionServiceX/converter_logic/rtf_to_txt_converter.py", line 25, in convert
    result = subprocess.run(command, check=True, stdout=subprocess.PIPE, stderr=subprocess.PIPE)
             ^^^^^^^^^^^^^^^^^^^^^^^^^^^^^^^^^^^^^^^^^^^^^^^^^^^^^^^^^^^^^^^^^^^^^^^^^^^^^^^^^^^
  File "/Library/Frameworks/Python.framework/Versions/3.12/lib/python3.12/subprocess.py", line 571, in run
    raise CalledProcessError(retcode, process.args,
subprocess.CalledProcessError: Command '['unrtf', '--text', '/var/folders/fh/ydk8l4t16ws2w9f2fctf7k_h0000gn/T/tmpeyn1jkg0.rtf']' returned non-zero exit status 10.

The above exception was the direct cause of the following exception:

Traceback (most recent call last):
  File "/Users/ag/PycharmProjects/FileConversionServiceX/app.py", line 46, in convert_file
    converter.convert(output_stream)
  File "/Users/ag/PycharmProjects/FileConversionServiceX/converter_logic/rtf_to_txt_converter.py", line 42, in convert
    raise RuntimeError("RTF to TXT conversion failed") from e
RuntimeError: RTF to TXT conversion failed

2024-04-09 16:41:53,028 - __main__ - DEBUG - Validating file: newTest.rtf
2024-04-09 16:41:53,031 - __main__ - DEBUG - scan_result: {scan_result}
2024-04-09 16:41:53,052 - converter_logic.rtf_to_txt_converter - ERROR - An error occurred during RTF to TXT conversion: Error (line 0): Cannot open input file

2024-04-09 16:41:53,053 - __main__ - ERROR - Conversion failed: Traceback (most recent call last):
  File "/Users/ag/PycharmProjects/FileConversionServiceX/converter_logic/rtf_to_txt_converter.py", line 25, in convert
    result = subprocess.run(command, check=True, stdout=subprocess.PIPE, stderr=subprocess.PIPE)
             ^^^^^^^^^^^^^^^^^^^^^^^^^^^^^^^^^^^^^^^^^^^^^^^^^^^^^^^^^^^^^^^^^^^^^^^^^^^^^^^^^^^
  File "/Library/Frameworks/Python.framework/Versions/3.12/lib/python3.12/subprocess.py", line 571, in run
    raise CalledProcessError(retcode, process.args,
subprocess.CalledProcessError: Command '['unrtf', '--text', '/var/folders/fh/ydk8l4t16ws2w9f2fctf7k_h0000gn/T/tmp4aja_56q.rtf']' returned non-zero exit status 10.

The above exception was the direct cause of the following exception:

Traceback (most recent call last):
  File "/Users/ag/PycharmProjects/FileConversionServiceX/app.py", line 46, in convert_file
    converter.convert(output_stream)
  File "/Users/ag/PycharmProjects/FileConversionServiceX/converter_logic/rtf_to_txt_converter.py", line 42, in convert
    raise RuntimeError("RTF to TXT conversion failed") from e
RuntimeError: RTF to TXT conversion failed

2024-04-09 16:42:04,308 - __main__ - DEBUG - Validating file: another_test_1.rtf
2024-04-09 16:42:04,309 - __main__ - DEBUG - scan_result: {scan_result}
2024-04-09 16:42:04,329 - converter_logic.rtf_to_txt_converter - ERROR - An error occurred during RTF to TXT conversion: Error (line 0): Cannot open input file

2024-04-09 16:42:04,330 - __main__ - ERROR - Conversion failed: Traceback (most recent call last):
  File "/Users/ag/PycharmProjects/FileConversionServiceX/converter_logic/rtf_to_txt_converter.py", line 25, in convert
    result = subprocess.run(command, check=True, stdout=subprocess.PIPE, stderr=subprocess.PIPE)
             ^^^^^^^^^^^^^^^^^^^^^^^^^^^^^^^^^^^^^^^^^^^^^^^^^^^^^^^^^^^^^^^^^^^^^^^^^^^^^^^^^^^
  File "/Library/Frameworks/Python.framework/Versions/3.12/lib/python3.12/subprocess.py", line 571, in run
    raise CalledProcessError(retcode, process.args,
subprocess.CalledProcessError: Command '['unrtf', '--text', '/var/folders/fh/ydk8l4t16ws2w9f2fctf7k_h0000gn/T/tmp8d6fbjlg.rtf']' returned non-zero exit status 10.

The above exception was the direct cause of the following exception:

Traceback (most recent call last):
  File "/Users/ag/PycharmProjects/FileConversionServiceX/app.py", line 46, in convert_file
    converter.convert(output_stream)
  File "/Users/ag/PycharmProjects/FileConversionServiceX/converter_logic/rtf_to_txt_converter.py", line 42, in convert
    raise RuntimeError("RTF to TXT conversion failed") from e
RuntimeError: RTF to TXT conversion failed

2024-04-09 16:45:12,378 - __main__ - DEBUG - Validating file: newTest.rtf
2024-04-09 16:45:12,382 - __main__ - DEBUG - scan_result: {scan_result}
2024-04-09 16:45:12,404 - converter_logic.rtf_to_txt_converter - ERROR - An error occurred during RTF to TXT conversion: Error (line 0): Cannot open input file

2024-04-09 16:45:12,406 - __main__ - ERROR - Conversion failed: Traceback (most recent call last):
  File "/Users/ag/PycharmProjects/FileConversionServiceX/converter_logic/rtf_to_txt_converter.py", line 25, in convert
    result = subprocess.run(command, check=True, stdout=subprocess.PIPE, stderr=subprocess.PIPE)
             ^^^^^^^^^^^^^^^^^^^^^^^^^^^^^^^^^^^^^^^^^^^^^^^^^^^^^^^^^^^^^^^^^^^^^^^^^^^^^^^^^^^
  File "/Library/Frameworks/Python.framework/Versions/3.12/lib/python3.12/subprocess.py", line 571, in run
    raise CalledProcessError(retcode, process.args,
subprocess.CalledProcessError: Command '['unrtf', '--text', '/var/folders/fh/ydk8l4t16ws2w9f2fctf7k_h0000gn/T/tmp88vvpwkq.rtf']' returned non-zero exit status 10.

The above exception was the direct cause of the following exception:

Traceback (most recent call last):
  File "/Users/ag/PycharmProjects/FileConversionServiceX/app.py", line 46, in convert_file
    converter.convert(output_stream)
  File "/Users/ag/PycharmProjects/FileConversionServiceX/converter_logic/rtf_to_txt_converter.py", line 42, in convert
    raise RuntimeError("RTF to TXT conversion failed") from e
RuntimeError: RTF to TXT conversion failed

2024-04-09 16:50:28,418 - __main__ - DEBUG - Validating file: newTest.rtf
2024-04-09 16:50:28,421 - __main__ - DEBUG - scan_result: {scan_result}
2024-04-09 16:50:50,890 - __main__ - DEBUG - Validating file: newTest.rtf
2024-04-09 16:50:50,893 - __main__ - DEBUG - scan_result: {scan_result}
2024-04-09 16:50:50,914 - converter_logic.rtf_to_txt_converter - ERROR - An error occurred during RTF to TXT conversion: Error (line 0): Cannot open input file

2024-04-09 16:50:50,917 - __main__ - ERROR - Conversion failed: Traceback (most recent call last):
  File "/Users/ag/PycharmProjects/FileConversionServiceX/converter_logic/rtf_to_txt_converter.py", line 25, in convert
    result = subprocess.run(command, check=True, stdout=subprocess.PIPE, stderr=subprocess.PIPE)
             ^^^^^^^^^^^^^^^^^^^^^^^^^^^^^^^^^^^^^^^^^^^^^^^^^^^^^^^^^^^^^^^^^^^^^^^^^^^^^^^^^^^
  File "/Library/Frameworks/Python.framework/Versions/3.12/lib/python3.12/subprocess.py", line 571, in run
    raise CalledProcessError(retcode, process.args,
subprocess.CalledProcessError: Command '['unrtf', '--text', '/var/folders/fh/ydk8l4t16ws2w9f2fctf7k_h0000gn/T/tmpe915m1pj.rtf']' returned non-zero exit status 10.

The above exception was the direct cause of the following exception:

Traceback (most recent call last):
  File "/Users/ag/PycharmProjects/FileConversionServiceX/app.py", line 46, in convert_file
    converter.convert(output_stream)
  File "/Users/ag/PycharmProjects/FileConversionServiceX/converter_logic/rtf_to_txt_converter.py", line 42, in convert
    raise RuntimeError("RTF to TXT conversion failed") from e
RuntimeError: RTF to TXT conversion failed

2024-04-09 16:51:40,105 - __main__ - DEBUG - Validating file: newTest.rtf
2024-04-09 16:51:40,107 - __main__ - DEBUG - scan_result: {scan_result}
2024-04-09 16:52:10,418 - __main__ - DEBUG - Validating file: ArchieGledhillCV_1.rtf
2024-04-09 16:52:10,421 - __main__ - DEBUG - scan_result: {scan_result}
2024-04-09 16:53:10,196 - __main__ - DEBUG - Validating file: ArchieGledhillCV_1.rtf
2024-04-09 16:53:10,197 - __main__ - DEBUG - scan_result: {scan_result}
2024-04-09 16:53:10,279 - __main__ - DEBUG - Validating file: ArchieGledhillCV_1.rtf
2024-04-09 16:53:10,282 - __main__ - DEBUG - scan_result: {scan_result}
2024-04-09 16:53:14,112 - __main__ - DEBUG - Validating file: ArchieGledhillCV_1.rtf
2024-04-09 16:53:14,115 - __main__ - DEBUG - scan_result: {scan_result}
2024-04-09 16:53:14,142 - __main__ - ERROR - Conversion failed: Traceback (most recent call last):
  File "/Users/ag/PycharmProjects/FileConversionServiceX/app.py", line 46, in convert_file
    converter.convert(output_stream)
  File "/Users/ag/PycharmProjects/FileConversionServiceX/converter_logic/rtf_to_txt_converter.py", line 27, in convert
    with open(temp_txt_path, 'rb') as temp_txt_file:
         ^^^^^^^^^^^^^^^^^^^^^^^^^
FileNotFoundError: [Errno 2] No such file or directory: '/var/folders/fh/ydk8l4t16ws2w9f2fctf7k_h0000gn/T/tmpkdzfe0uh.rtf.txt'

2024-04-09 16:53:23,760 - __main__ - DEBUG - Validating file: ArchieGledhillCV_1.rtf
2024-04-09 16:53:23,762 - __main__ - DEBUG - scan_result: {scan_result}
2024-04-09 16:53:24,851 - __main__ - DEBUG - Validating file: ArchieGledhillCV_1.rtf
2024-04-09 16:53:24,854 - __main__ - DEBUG - scan_result: {scan_result}
2024-04-09 16:53:25,946 - __main__ - DEBUG - Validating file: ArchieGledhillCV_1.rtf
2024-04-09 16:53:25,948 - __main__ - DEBUG - scan_result: {scan_result}
2024-04-09 16:53:28,153 - __main__ - DEBUG - Validating file: ArchieGledhillCV_1.rtf
2024-04-09 16:53:28,156 - __main__ - DEBUG - scan_result: {scan_result}
2024-04-09 16:55:46,735 - __main__ - DEBUG - Validating file: output.txt
2024-04-09 16:55:46,737 - __main__ - DEBUG - scan_result: {scan_result}
2024-04-09 16:56:14,304 - __main__ - DEBUG - Validating file: newTest.txt
2024-04-09 16:56:14,307 - __main__ - DEBUG - scan_result: {scan_result}
2024-04-09 16:56:43,445 - __main__ - DEBUG - Validating file: Reportp1.docx
2024-04-09 16:56:43,468 - __main__ - DEBUG - scan_result: {scan_result}
2024-04-09 16:56:43,484 - converter_logic.docx_to_rtf_converter - DEBUG - Created temporary directory: /var/folders/fh/ydk8l4t16ws2w9f2fctf7k_h0000gn/T/tmpubl40suf
2024-04-09 16:56:43,485 - converter_logic.docx_to_rtf_converter - DEBUG - Temporary paths set for input: /var/folders/fh/ydk8l4t16ws2w9f2fctf7k_h0000gn/T/tmpubl40suf/document.docx and output: /var/folders/fh/ydk8l4t16ws2w9f2fctf7k_h0000gn/T/tmpubl40suf/document.rtf
2024-04-09 16:56:43,488 - converter_logic.docx_to_rtf_converter - DEBUG - Wrote input stream to temporary file
2024-04-09 16:56:43,488 - converter_logic.docx_to_rtf_converter - DEBUG - Executing command: pandoc -s /var/folders/fh/ydk8l4t16ws2w9f2fctf7k_h0000gn/T/tmpubl40suf/document.docx -o /var/folders/fh/ydk8l4t16ws2w9f2fctf7k_h0000gn/T/tmpubl40suf/document.rtf
2024-04-09 16:56:46,867 - converter_logic.docx_to_rtf_converter - DEBUG - Pandoc conversion executed successfully
2024-04-09 16:56:46,869 - converter_logic.docx_to_rtf_converter - DEBUG - Read converted RTF content back into the output stream
2024-04-09 16:57:12,009 - __main__ - DEBUG - Validating file: ArchieGledhillCV.pdf
2024-04-09 16:57:12,072 - __main__ - DEBUG - scan_result: {scan_result}
2024-04-09 16:58:03,110 - __main__ - DEBUG - Validating file: ArchieGledhillCV.pdf
2024-04-09 16:58:03,113 - __main__ - DEBUG - scan_result: {scan_result}
2024-04-09 16:58:04,661 - __main__ - DEBUG - Validating file: ArchieGledhillCV.pdf
2024-04-09 16:58:04,665 - __main__ - DEBUG - scan_result: {scan_result}
2024-04-09 16:58:43,796 - __main__ - DEBUG - Validating file: ArchieGledhillCV.pdf
2024-04-09 16:58:43,799 - __main__ - DEBUG - scan_result: {scan_result}
2024-04-09 16:58:45,688 - __main__ - DEBUG - Validating file: ArchieGledhillCV.pdf
2024-04-09 16:58:45,691 - __main__ - DEBUG - scan_result: {scan_result}
2024-04-09 17:00:56,161 - __main__ - DEBUG - Validating file: ArchieGledhillCV.pdf
2024-04-09 17:00:56,164 - __main__ - DEBUG - scan_result: {scan_result}
2024-04-09 18:39:17,611 - __main__ - DEBUG - Validating file: ArchieGledhillCV_2.docx
2024-04-09 18:39:17,616 - __main__ - DEBUG - scan_result: {scan_result}
2024-04-09 18:39:17,625 - converter_logic.docx_to_rtf_converter - DEBUG - Created temporary directory: /var/folders/fh/ydk8l4t16ws2w9f2fctf7k_h0000gn/T/tmp7f_8hat8
2024-04-09 18:39:17,625 - converter_logic.docx_to_rtf_converter - DEBUG - Temporary paths set for input: /var/folders/fh/ydk8l4t16ws2w9f2fctf7k_h0000gn/T/tmp7f_8hat8/document.docx and output: /var/folders/fh/ydk8l4t16ws2w9f2fctf7k_h0000gn/T/tmp7f_8hat8/document.rtf
2024-04-09 18:39:17,625 - converter_logic.docx_to_rtf_converter - DEBUG - Wrote input stream to temporary file
2024-04-09 18:39:17,626 - converter_logic.docx_to_rtf_converter - DEBUG - Executing command: pandoc -s /var/folders/fh/ydk8l4t16ws2w9f2fctf7k_h0000gn/T/tmp7f_8hat8/document.docx -o /var/folders/fh/ydk8l4t16ws2w9f2fctf7k_h0000gn/T/tmp7f_8hat8/document.rtf
2024-04-09 18:39:17,951 - converter_logic.docx_to_rtf_converter - DEBUG - Pandoc conversion executed successfully
2024-04-09 18:39:17,951 - converter_logic.docx_to_rtf_converter - DEBUG - Read converted RTF content back into the output stream
2024-04-09 18:39:21,184 - __main__ - DEBUG - Validating file: ArchieGledhillCV_2.docx
2024-04-09 18:39:21,187 - __main__ - DEBUG - scan_result: {scan_result}
2024-04-09 18:39:36,246 - __main__ - DEBUG - Validating file: Reportp1_4.pdf
2024-04-09 18:39:38,032 - __main__ - DEBUG - scan_result: {scan_result}
2024-04-09 18:42:29,548 - __main__ - DEBUG - Validating file: TESTINGDOC_1.rtf
2024-04-09 18:42:29,554 - __main__ - DEBUG - scan_result: {scan_result}
2024-04-09 18:42:29,564 - __main__ - ERROR - Conversion failed: Traceback (most recent call last):
  File "/Users/ag/PycharmProjects/FileConversionServiceX/app.py", line 46, in convert_file
    converter.convert(output_stream)
  File "/Users/ag/PycharmProjects/FileConversionServiceX/converter_logic/rtf_to_txt_converter.py", line 7, in convert
    raise NotImplemented
TypeError: exceptions must derive from BaseException

2024-04-09 18:44:13,388 - __main__ - DEBUG - Validating file: TESTINGDOC_1.rtf
2024-04-09 18:44:13,390 - __main__ - DEBUG - scan_result: {scan_result}
2024-04-09 18:44:19,065 - __main__ - DEBUG - Validating file: TESTINGDOC_1.rtf
2024-04-09 18:44:19,068 - __main__ - DEBUG - scan_result: {scan_result}
2024-04-09 18:44:19,076 - converter_logic.rtf_to_docx_converter - INFO - Temporary RTF path: /var/folders/fh/ydk8l4t16ws2w9f2fctf7k_h0000gn/T/tmprfxwxqg9/input.rtf
2024-04-09 18:44:19,076 - converter_logic.rtf_to_docx_converter - INFO - Temporary DOCX path: /var/folders/fh/ydk8l4t16ws2w9f2fctf7k_h0000gn/T/tmprfxwxqg9/input.docx
2024-04-09 18:44:19,076 - converter_logic.rtf_to_docx_converter - INFO - Written RTF content to temporary file
2024-04-09 18:44:19,076 - converter_logic.rtf_to_docx_converter - INFO - Executing command: /Applications/LibreOffice.app/Contents/MacOS/soffice --headless --convert-to docx --outdir /var/folders/fh/ydk8l4t16ws2w9f2fctf7k_h0000gn/T/tmprfxwxqg9 /var/folders/fh/ydk8l4t16ws2w9f2fctf7k_h0000gn/T/tmprfxwxqg9/input.rtf
2024-04-09 18:44:20,163 - converter_logic.rtf_to_docx_converter - INFO - Conversion command executed successfully
2024-04-09 18:44:36,656 - __main__ - DEBUG - Validating file: Reportp1_4.pdf
2024-04-09 18:44:36,666 - __main__ - DEBUG - scan_result: {scan_result}
2024-04-11 12:48:19,998 - __main__ - DEBUG - Validating file: Reportp1_4_7.rtf
2024-04-11 12:48:20,055 - __main__ - DEBUG - scan_result: {scan_result}
2024-04-11 12:48:20,092 - converter_logic.rtf_to_docx_converter - INFO - Temporary RTF path: /var/folders/fh/ydk8l4t16ws2w9f2fctf7k_h0000gn/T/tmpsqgxcdmy/input.rtf
2024-04-11 12:48:20,092 - converter_logic.rtf_to_docx_converter - INFO - Temporary DOCX path: /var/folders/fh/ydk8l4t16ws2w9f2fctf7k_h0000gn/T/tmpsqgxcdmy/input.docx
2024-04-11 12:48:20,094 - converter_logic.rtf_to_docx_converter - INFO - Written RTF content to temporary file
2024-04-11 12:48:20,096 - __main__ - ERROR - Conversion failed: Traceback (most recent call last):
  File "/Users/ag/PycharmProjects/FileConversionServiceX/app.py", line 53, in convert_file
    converter.convert(output_stream)
  File "/Users/ag/PycharmProjects/FileConversionServiceX/converter_logic/rtf_to_docx_converter.py", line 40, in convert
    logger.info(f"Executing command: {' '.join(cmd)}")
                                      ^^^^^^^^^^^^^
TypeError: sequence item 0: expected str instance, NoneType found

2024-04-11 12:49:29,464 - __main__ - DEBUG - Validating file: Reportp1_4_6.rtf
2024-04-11 12:49:29,518 - __main__ - DEBUG - scan_result: {scan_result}
2024-04-11 12:49:29,557 - converter_logic.rtf_to_docx_converter - INFO - Temporary RTF path: /var/folders/fh/ydk8l4t16ws2w9f2fctf7k_h0000gn/T/tmpys61cx35/input.rtf
2024-04-11 12:49:29,557 - converter_logic.rtf_to_docx_converter - INFO - Temporary DOCX path: /var/folders/fh/ydk8l4t16ws2w9f2fctf7k_h0000gn/T/tmpys61cx35/input.docx
2024-04-11 12:49:29,559 - converter_logic.rtf_to_docx_converter - INFO - Written RTF content to temporary file
2024-04-11 12:49:29,565 - __main__ - ERROR - Conversion failed: Traceback (most recent call last):
  File "/Users/ag/PycharmProjects/FileConversionServiceX/app.py", line 53, in convert_file
    converter.convert(output_stream)
  File "/Users/ag/PycharmProjects/FileConversionServiceX/converter_logic/rtf_to_docx_converter.py", line 43, in convert
    subprocess.run(cmd, check=True, capture_output=True)
  File "/Library/Frameworks/Python.framework/Versions/3.12/lib/python3.12/subprocess.py", line 548, in run
    with Popen(*popenargs, **kwargs) as process:
         ^^^^^^^^^^^^^^^^^^^^^^^^^^^
  File "/Library/Frameworks/Python.framework/Versions/3.12/lib/python3.12/subprocess.py", line 1026, in __init__
    self._execute_child(args, executable, preexec_fn, close_fds,
  File "/Library/Frameworks/Python.framework/Versions/3.12/lib/python3.12/subprocess.py", line 1824, in _execute_child
    and os.path.dirname(executable)
        ^^^^^^^^^^^^^^^^^^^^^^^^^^^
  File "<frozen posixpath>", line 181, in dirname
TypeError: expected str, bytes or os.PathLike object, not NoneType

2024-04-11 12:51:27,036 - __main__ - DEBUG - Validating file: Reportp1_4_6.rtf
2024-04-11 12:51:27,091 - __main__ - DEBUG - scan_result: {scan_result}
2024-04-11 12:51:27,127 - converter_logic.rtf_to_docx_converter - INFO - Temporary RTF path: /var/folders/fh/ydk8l4t16ws2w9f2fctf7k_h0000gn/T/tmph0t1eoxe/input.rtf
2024-04-11 12:51:27,127 - converter_logic.rtf_to_docx_converter - INFO - Temporary DOCX path: /var/folders/fh/ydk8l4t16ws2w9f2fctf7k_h0000gn/T/tmph0t1eoxe/input.docx
2024-04-11 12:51:27,130 - converter_logic.rtf_to_docx_converter - INFO - Written RTF content to temporary file
2024-04-11 12:51:29,316 - converter_logic.rtf_to_docx_converter - INFO - Conversion command executed successfully
2024-04-11 12:55:47,550 - __main__ - DEBUG - Validating file: Reportp1_2.docx
2024-04-11 12:55:47,579 - __main__ - DEBUG - scan_result: {scan_result}
2024-04-11 12:55:47,599 - converter_logic.docx_to_rtf_converter - DEBUG - Created temporary directory: /var/folders/fh/ydk8l4t16ws2w9f2fctf7k_h0000gn/T/tmp_h6gevg6
2024-04-11 12:55:47,600 - converter_logic.docx_to_rtf_converter - DEBUG - Temporary paths set for input: /var/folders/fh/ydk8l4t16ws2w9f2fctf7k_h0000gn/T/tmp_h6gevg6/document.docx and output: /var/folders/fh/ydk8l4t16ws2w9f2fctf7k_h0000gn/T/tmp_h6gevg6/document.rtf
2024-04-11 12:55:47,604 - converter_logic.docx_to_rtf_converter - DEBUG - Wrote input stream to temporary file
2024-04-11 12:55:47,604 - converter_logic.docx_to_rtf_converter - DEBUG - Executing command: pandoc -s /var/folders/fh/ydk8l4t16ws2w9f2fctf7k_h0000gn/T/tmp_h6gevg6/document.docx -o /var/folders/fh/ydk8l4t16ws2w9f2fctf7k_h0000gn/T/tmp_h6gevg6/document.rtf
2024-04-11 12:55:51,490 - converter_logic.docx_to_rtf_converter - DEBUG - Pandoc conversion executed successfully
2024-04-11 12:55:51,493 - converter_logic.docx_to_rtf_converter - DEBUG - Read converted RTF content back into the output stream
2024-04-11 13:00:58,316 - __main__ - DEBUG - Validating file: ArchieGledhillCV_4.docx
2024-04-11 13:00:58,364 - __main__ - DEBUG - scan_result: {scan_result}
2024-04-11 13:00:58,375 - converter_logic.docx_to_rtf_converter - DEBUG - Created temporary directory: /var/folders/fh/ydk8l4t16ws2w9f2fctf7k_h0000gn/T/tmpn13obi6k
2024-04-11 13:00:58,375 - converter_logic.docx_to_rtf_converter - DEBUG - Temporary paths set for input: /var/folders/fh/ydk8l4t16ws2w9f2fctf7k_h0000gn/T/tmpn13obi6k/document.docx and output: /var/folders/fh/ydk8l4t16ws2w9f2fctf7k_h0000gn/T/tmpn13obi6k/document.rtf
2024-04-11 13:00:58,376 - converter_logic.docx_to_rtf_converter - DEBUG - Wrote input stream to temporary file
2024-04-11 13:00:58,376 - converter_logic.docx_to_rtf_converter - DEBUG - Executing command: pandoc -s /var/folders/fh/ydk8l4t16ws2w9f2fctf7k_h0000gn/T/tmpn13obi6k/document.docx -o /var/folders/fh/ydk8l4t16ws2w9f2fctf7k_h0000gn/T/tmpn13obi6k/document.rtf
2024-04-11 13:00:58,430 - converter_logic.docx_to_rtf_converter - DEBUG - Pandoc conversion executed successfully
2024-04-11 13:00:58,430 - converter_logic.docx_to_rtf_converter - DEBUG - Read converted RTF content back into the output stream
2024-04-11 13:01:02,682 - __main__ - DEBUG - Validating file: ArchieGledhillCV_4.docx
2024-04-11 13:01:02,685 - __main__ - DEBUG - scan_result: {scan_result}
2024-04-11 13:01:38,438 - __main__ - DEBUG - Validating file: Reportp1_4_6.docx
2024-04-11 13:01:41,286 - __main__ - DEBUG - Validating file: Reportp1_4_6.docx
2024-04-11 13:01:43,383 - __main__ - DEBUG - scan_result: {scan_result}
2024-04-11 13:01:46,305 - __main__ - DEBUG - scan_result: {scan_result}
2024-04-11 13:02:33,728 - __main__ - DEBUG - Validating file: Reportp1_4_6.docx
2024-04-11 13:02:33,756 - __main__ - DEBUG - scan_result: {scan_result}
2024-04-11 13:03:10,330 - __main__ - DEBUG - Validating file: Reportp1_4_6.docx
2024-04-11 13:03:10,356 - __main__ - DEBUG - scan_result: {scan_result}
2024-04-11 13:06:18,688 - __main__ - DEBUG - Validating file: Reportp1_4_6.docx
2024-04-11 13:06:18,712 - __main__ - DEBUG - scan_result: {scan_result}
2024-04-11 13:06:22,151 - __main__ - DEBUG - Validating file: Reportp1_4_6.docx
2024-04-11 13:06:22,178 - __main__ - DEBUG - scan_result: {scan_result}
2024-04-11 13:07:35,862 - __main__ - DEBUG - Validating file: Reportp1_4_6.docx
2024-04-11 13:07:35,891 - __main__ - DEBUG - scan_result: {scan_result}
2024-04-11 13:07:40,344 - __main__ - DEBUG - Validating file: Reportp1_4_6.docx
2024-04-11 13:07:40,371 - __main__ - DEBUG - scan_result: {scan_result}
2024-04-11 13:10:20,664 - __main__ - DEBUG - Validating file: Reportp1_4_8.rtf
2024-04-11 13:10:20,723 - __main__ - DEBUG - scan_result: {scan_result}
2024-04-11 13:10:20,761 - converter_logic.rtf_to_pdf_converter - INFO - Temporary RTF path: /var/folders/fh/ydk8l4t16ws2w9f2fctf7k_h0000gn/T/tmpyecfpv6x/input.rtf
2024-04-11 13:10:20,761 - converter_logic.rtf_to_pdf_converter - INFO - Temporary PDF path: /var/folders/fh/ydk8l4t16ws2w9f2fctf7k_h0000gn/T/tmpyecfpv6x/input.pdf
2024-04-11 13:10:20,764 - converter_logic.rtf_to_pdf_converter - INFO - Written RTF content to temporary file
2024-04-11 13:10:20,764 - converter_logic.rtf_to_pdf_converter - INFO - Executing command: /Applications/LibreOffice.app/Contents/MacOS/soffice --headless --convert-to pdf --outdir /var/folders/fh/ydk8l4t16ws2w9f2fctf7k_h0000gn/T/tmpyecfpv6x /var/folders/fh/ydk8l4t16ws2w9f2fctf7k_h0000gn/T/tmpyecfpv6x/input.rtf
2024-04-11 13:10:22,673 - converter_logic.rtf_to_pdf_converter - INFO - Conversion command executed successfully
2024-04-11 13:14:29,014 - __main__ - DEBUG - Validating file: Reportp1_4_6.docx
2024-04-11 13:14:29,043 - __main__ - DEBUG - scan_result: {scan_result}
2024-04-11 13:14:29,065 - converter_logic.docx_to_rtf_converter - DEBUG - Created temporary directory: /var/folders/fh/ydk8l4t16ws2w9f2fctf7k_h0000gn/T/tmp25248iea
2024-04-11 13:14:29,065 - converter_logic.docx_to_rtf_converter - DEBUG - Temporary paths set for input: /var/folders/fh/ydk8l4t16ws2w9f2fctf7k_h0000gn/T/tmp25248iea/document.docx and output: /var/folders/fh/ydk8l4t16ws2w9f2fctf7k_h0000gn/T/tmp25248iea/document.rtf
2024-04-11 13:14:29,068 - converter_logic.docx_to_rtf_converter - DEBUG - Wrote input stream to temporary file
2024-04-11 13:14:29,069 - converter_logic.docx_to_rtf_converter - DEBUG - Executing command: pandoc -s /var/folders/fh/ydk8l4t16ws2w9f2fctf7k_h0000gn/T/tmp25248iea/document.docx -o /var/folders/fh/ydk8l4t16ws2w9f2fctf7k_h0000gn/T/tmp25248iea/document.rtf
2024-04-11 13:14:32,981 - converter_logic.docx_to_rtf_converter - DEBUG - Pandoc conversion executed successfully
2024-04-11 13:14:32,984 - converter_logic.docx_to_rtf_converter - DEBUG - Read converted RTF content back into the output stream
2024-04-11 13:16:10,870 - __main__ - DEBUG - Validating file: ArchieGledhillCV_4.pdf
2024-04-11 13:16:10,894 - __main__ - DEBUG - scan_result: {scan_result}
2024-04-11 13:16:13,209 - __main__ - DEBUG - Validating file: ArchieGledhillCV_4.pdf
2024-04-11 13:16:13,212 - __main__ - DEBUG - scan_result: {scan_result}
2024-04-11 13:16:16,361 - __main__ - DEBUG - Validating file: ArchieGledhillCV_4.pdf
2024-04-11 13:16:16,364 - __main__ - DEBUG - scan_result: {scan_result}
2024-04-11 13:16:20,185 - __main__ - DEBUG - Validating file: ArchieGledhillCV_4.pdf
2024-04-11 13:16:20,188 - __main__ - DEBUG - scan_result: {scan_result}
2024-04-11 13:16:31,054 - __main__ - DEBUG - Validating file: Reportp1_2.docx
2024-04-11 13:16:31,083 - __main__ - DEBUG - scan_result: {scan_result}
