2024-04-09 13:26:56,253 - __main__ - DEBUG - Validating file: newTest.txt
2024-04-09 13:26:56,264 - __main__ - DEBUG - scan_result: {scan_result}
2024-04-09 13:39:18,332 - __main__ - DEBUG - Validating file: TESTINGDOC.txt
2024-04-09 13:39:18,344 - __main__ - DEBUG - scan_result: {scan_result}
2024-04-09 17:21:53,973 - __main__ - DEBUG - Validating file: Reportp1.docx
2024-04-09 17:21:53,997 - __main__ - DEBUG - scan_result: {scan_result}
2024-04-09 17:23:28,251 - __main__ - DEBUG - Validating file: ArchieGledhillCV.pdf
2024-04-09 17:23:28,256 - __main__ - DEBUG - scan_result: {scan_result}
2024-04-09 17:23:33,155 - __main__ - DEBUG - Validating file: ArchieGledhillCV.pdf
2024-04-09 17:23:33,158 - __main__ - DEBUG - scan_result: {scan_result}
2024-04-09 17:23:42,689 - __main__ - DEBUG - Validating file: Reportp1.docx
2024-04-09 17:23:42,715 - __main__ - DEBUG - scan_result: {scan_result}
2024-04-09 17:23:48,618 - __main__ - DEBUG - Validating file: Reportp1.docx
2024-04-09 17:23:48,642 - __main__ - DEBUG - scan_result: {scan_result}
2024-04-09 17:29:42,885 - __main__ - DEBUG - Validating file: largefile.docx
2024-04-09 17:29:44,390 - __main__ - DEBUG - scan_result: {scan_result}
2024-04-09 17:30:43,671 - __main__ - DEBUG - Validating file: ArchieGledhillCV_2.docx
2024-04-09 17:30:43,846 - __main__ - DEBUG - scan_result: {scan_result}
2024-04-09 17:31:40,096 - converter_logic.docx_to_pdf_converter - ERROR - Expected PDF file was not created.
2024-04-09 17:31:40,104 - __main__ - ERROR - Conversion failed: Traceback (most recent call last):
  File "/Users/ag/PycharmProjects/FileConversionServiceX/app.py", line 46, in convert_file
    converter.convert(output_stream)
  File "/Users/ag/PycharmProjects/FileConversionServiceX/converter_logic/docx_to_pdf_converter.py", line 31, in convert
    raise FileNotFoundError("Expected PDF file was not created.")
FileNotFoundError: Expected PDF file was not created.

